<mujoco model="Space Dragger">
  <option timestep="0.005"/>

  <asset>
    <texture type="skybox" builtin="gradient" rgb1=".0 .0 .0" rgb2="0. 0.0 .1" width="512" height="512"/>
    <texture name="body" type="cube" builtin="flat" mark="cross" width="127" height="1278"
             rgb1="0.4 0.4 0.4" rgb2="0.4 0.4 0.4" markrgb="0 0 0" random="0.01"/>
    <material name="body" texture="body" texuniform="true"/>
    <texture name="grid" type="2d" builtin="checker" width="512" height="512" rgb1=".6 .6 .6" rgb2=".9 .9 .9"/>
    <material name="grid" texture="grid" texrepeat="1 1" texuniform="true" reflectance=".2"/>
  </asset>

  <default>
    <motor ctrlrange="-1 1" ctrllimited="true"/>
    <default class="body">
      <geom type="capsule" condim="1" friction=".7" solimp=".9 .99 .003" solref=".015 1" material="body"/>
      <joint type="hinge" damping=".2" stiffness="1" armature=".01" limited="true" solimplimit="0 .99 .01"/>
      <default class="big_joint">
        <joint damping="5" stiffness="10"/>
        <default class="big_stiff_joint">
          <joint stiffness="20"/>
        </default>
      </default>
    </default>
    
    <default class="target_slider">
        <joint armature="10000" damping="10000" limited="true" pos="0 0 0" range="-1000 1000" ref=".1" stiffness="0" type="slide"/>
        <geom conaffinity="0" pos="0 0 0" rgba=" 1 0 1 0.5" size="0.005" type="sphere"/>
    </default>
    
    
  </default>

  <visual>
    <map force="0.1" zfar="30"/>
    <rgba haze="0.15 0.25 0.35 .1"/>
    <quality shadowsize="4096"/>
    <global offwidth="800" offheight="800"/>
  </visual>

  <worldbody>
    <geom name="floor" size="0 0 .05" type="plane" material="grid" condim="3"/>
    <light name="spotlight" mode="targetbodycom" target="torso"
           diffuse=".8 .8 .8" specular="0.3 0.3 0.3" pos="0 -20 4" cutoff="10"/>

    <body name="torso" pos="0 0 .1" childclass="body">
      <light name="top" pos="0 0 2" mode="trackcom"/>
      <camera name="back" pos="-3 0 1" xyaxes="0 -1 0 1 0 5" mode="trackcom"/>
      <camera name="front" pos="3 0 1" xyaxes="0 1 0 -1 0 5" mode="trackcom"/>
      <camera name="side" pos="0 -3 1" xyaxes="1 0 0 0 1 3" mode="trackcom"/>
      <camera name="isometric" pos="2 -2 1" xyaxes="1 1 0 0 1 3" mode="trackcom"/>
      <freejoint name="root"/>
      <geom name="base" type="box" size=".2 .1 .1" density="300"/>
      <site name="robot_sensor_zone" rgba="1 1 0 0.1" size="0.3" type="sphere"/>
<!--      <geom name="waist2" fromto="-.3 0.1 0 .3 0.1 0" size=".02" density="1000"/>-->
<!--      <geom name="waist3" fromto="-.3 -.1 0 .3 -.1 0" size=".02" density="1000"/>-->

      <body name="arm1" pos="0.25 .0 .1" euler="0 45 0">
        <joint name="arm1" axis="0 1 0" range="0 90"/>
        <geom name="arm1" fromto="0 0 0 .0 .0 .25" size=".04" density="500" rgba=".9 .9 .9 .9"/>
        <body name="arm2" pos="0 .0 .25" euler="0 45 0">
          <joint name="arm2" axis="0 1 0" range="0 90"/>
          <geom name="arm2" fromto="0 0 0 .0 .0 .15" size=".031" rgba="0.6 0.6 0.6 .9" density="500"/>
          <geom name="foot" pos="0 0 .15" type="sphere" size=".04" rgba=".1 .1 .1 1"/>
        </body>
      </body>
    </body>
  </worldbody>

  <actuator>
    <motor name="arm1"  gear="20"  joint="arm1"/>
    <motor name="arm2" gear="20"  joint="arm2"/>
  </actuator>
  
  <sensor>
      <jointpos joint="arm1" noise="0"/>
      <jointpos joint="arm2" noise="0"/>
      <framepos objtype="site"  objname="robot_sensor_zone"  noise="0"/>
  </sensor>
  
</mujoco>

